Workbook

Sheet Assumptions
A1: BABB WORKS INC. — COST ANALYSIS | D1: Source: 2026 CRA / OEB / WSIB rates
A2: All figures in Canadian Dollars (CAD). Blue = editable input. Black = formula.
A4: FACILITY ASSUMPTIONS
A5: Leasable Area (sq ft) | B5: 4000 | D5: Confirmed lease
A6: Annual Lease Rate ($/sq ft, all-in TMI) | B6: 9 | D6: All-in gross including TMI
A7: Annual Rent | B7: =B5*B6 -> 36000 | D7: area × rate
A8: Monthly Rent | B8: =B7/12 -> 3000
A10: ELECTRICITY (Ontario RPP — Small Business < 50 kW)
A11: Blended Electricity Rate (¢/kWh) | B11: 0.13 | C11: $/kWh | D11: OEB TOU blended avg ~13¢ incl. delivery + reg
A12: Ontario Electricity Rebate (OER) | B12: 0.235 | D12: 23.5% rebate eff. Nov 1, 2025
A13: Effective Rate After OER ($/kWh) | B13: =B11*(1-B12) -> 0.09945
A14: Estimated Monthly Usage (kWh) | B14: 3500 | D14: Assembly floor + testing + HVAC + lighting
A15: Monthly Electricity Cost | B15: =B13*B14 -> 348.075
A16: Annual Electricity Cost | B16: =B15*12 -> 4176.9
A18: EMPLOYER STATUTORY RATES — 2026
A19: CPP Employer Rate | B19: 0.0595 | D19: 5.95% on pensionable earnings to YMPE $74,600
A20: CPP Basic Exemption | B20: 3500 | D20: Source: CRA 2026
A21: CPP YMPE (Year Max Pensionable Earnings) | B21: 74600 | D21: Source: CRA 2026
A22: CPP2 Rate (on earnings $74,600–$85,000) | B22: 0.04 | D22: Second ceiling YAMPE = $85,000
A23: EI Employer Premium Rate | B23: 0.02282 | D23: 1.4× employee rate of 1.63% = 2.282%
A24: EI Max Insurable Earnings | B24: 68900 | D24: Source: CEIC 2026
A25: EI Max Employer Premium / Employee | B25: 1572.3 | D25: Source: CEIC 2026
A26: WSIB Premium (electronics mfg class) | B26: 0.0123 | D26: $1.23/$100 avg 2026 — actual varies by NAICS
A27: Vacation Pay (minimum 2 weeks) | B27: 0.04 | D27: ESA minimum 4% (6% after 5 yrs)
A28: EHT (Employer Health Tax) | B28: 0 | D28: Exempt on first $1M payroll (through 2028)
A29: Public Holidays (9 days Ontario) | B29: 9 | D29: ESA: 9 statutory holidays per year
A31: OTHER OPERATING ASSUMPTIONS
A32: Commercial Insurance (annual) | B32: 8500 | D32: CGL + property + E&O — small mfg estimate
A33: Internet / Telecom (monthly) | B33: 350 | D33: Business fibre + VoIP
A34: Accounting / Legal (annual) | B34: 12000 | D34: Bookkeeper + annual corp filing + legal retainer
A35: Office Supplies & Misc (monthly) | B35: 400
A36: Software Licenses (monthly) | B36: 500 | D36: EDA, ERP lite, Office, cloud, backups
A37: Shipping / Courier (monthly) | B37: 600 | D37: Purolator, UPS, component receiving
A38: HST Rate | B38: 0.13 | D38: Ontario HST — reclaimable via ITC

Sheet Startup Capital
A1: PHASE 1 STARTUP CAPITAL — ONE-TIME COSTS
A2: All costs before HST (reclaimable via ITC for registered businesses)
A4: Item | B4: Qty | C4: Unit Cost | D4: Total | E4: Notes / Source
A5: FACILITY BUILDOUT
A6: ESD epoxy flooring (4,000 sq ft) | B6: 4000 | C6: 4.5 | D6: =B6*C6 -> 18000 | E6: Conductive epoxy — $3.50–$6/sq ft installed
A7: Electrical panel upgrade (200A service) | B7: 1 | C7: 8500 | D7: =B7*C7 -> 8500 | E7: Licensed electrician, permits, inspection
A8: Dedicated circuits for equipment (20A×12) | B8: 12 | C8: 650 | D8: =B8*C8 -> 7800 | E8: Assembly floor + testing lab + server
A9: HVAC supplemental (humidity control) | B9: 1 | C9: 6500 | D9: =B9*C9 -> 6500 | E9: Critical for solder paste / component storage
A10: LED lighting upgrade (high-CRI assembly) | B10: 1 | C10: 4200 | D10: =B10*C10 -> 4200 | E10: 5000K high-CRI panels, task lighting
A11: Fire suppression (clean agent, server room) | B11: 1 | C11: 3500 | D11: =B11*C11 -> 3500 | E11: FM-200 or Novec for electronics areas
A12: Network cabling (Cat6A, 24 drops) | B12: 24 | C12: 185 | D12: =B12*C12 -> 4440 | E12: Structured cabling + patch panel + rack
A13: Security system (cameras + access control) | B13: 1 | C13: 3800 | D13: =B13*C13 -> 3800 | E13: IP cameras, card reader, monitoring
A14: Signage (exterior + interior wayfinding) | B14: 1 | C14: 2500 | D14: =B14*C14 -> 2500 | E14: Building signage + ESD zone markings
A15: Subtotal — Facility Buildout | D15: =SUM(D6:D14) -> 59240
A17: ASSEMBLY EQUIPMENT
A18: ESD workstations (Treston-class, full kit) | B18: 6 | C18: 3200 | D18: =B18*C18 -> 19200 | E18: Bench + mat + wrist strap + grounding + task light
A19: ESD chairs (adjustable, conductive casters) | B19: 6 | C19: 450 | D19: =B19*C19 -> 2700 | E19: IEC 61340 compliant
A20: Soldering stations (Hakko FX-951 or equiv.) | B20: 6 | C20: 680 | D20: =B20*C20 -> 4080 | E20: Digital, ESD-safe, tip variety
A21: Hot air rework station (Hakko FR-810) | B21: 2 | C21: 1850 | D21: =B21*C21 -> 3700 | E21: SMD rework, BGA capability
A22: Stereo microscope (Amscope, LED ring) | B22: 4 | C22: 850 | D22: =B22*C22 -> 3400 | E22: 7×–45× zoom, boom stand
A23: Solder paste printer (manual stencil) | B23: 1 | C23: 2800 | D23: =B23*C23 -> 2800 | E23: Manual/semi-auto stencil printer
A24: Desktop pick & place (Neoden YY1/TronStol) | B24: 1 | C24: 12500 | D24: =B24*C24 -> 12500 | E24: 46 feeders, vision system — prototype/small batch
A25: Reflow oven (Neoden T5 or equiv. 5-zone) | B25: 1 | C25: 8500 | D25: =B25*C25 -> 8500 | E25: Lead-free capable, N2 optional
A26: PCB depaneling (V-cut scorer) | B26: 1 | C26: 1800 | D26: =B26*C26 -> 1800 | E26: Manual V-groove separator
A27: Ultrasonic cleaner (6L, heated) | B27: 1 | C27: 650 | D27: =B27*C27 -> 650 | E27: Post-solder PCB cleaning
A28: Fume extraction (4-port, HEPA/carbon) | B28: 2 | C28: 1200 | D28: =B28*C28 -> 2400 | E28: Solder fume + flux vapour
A29: ESD tool kits (tweezers, probes, cutters) | B29: 6 | C29: 180 | D29: =B29*C29 -> 1080 | E29: Wiha / Wera anti-static sets
... A31: Wire harness / cable assembly tools | B31: 1 | C31: 2200 | D31: =B31*C31 -> 2200 | E31: Crimpers, strippers, testers
A32: Subtotal — Assembly Equipment | D32: =SUM(D18:D31) -> 69510
A34: TEST & MEASUREMENT
A35: Digital oscilloscope (Rigol DS1104Z+) | B35: 2 | C35: 650 | D35: =B35*C35 -> 1300 | E35: 100 MHz, 4-channel — firmware debug
A36: Bench multimeter (Keysight 34461A class) | B36: 3 | C36: 420 | D36: =B36*C36 -> 1260 | E36: 6.5-digit for production QC
A37: Programmable power supply (dual ch, 30V/5A) | B37: 2 | C37: 550 | D37: =B37*C37 -> 1100 | E37: Rigol DP832 class
A38: Logic analyzer (Saleae Logic Pro 16) | B38: 2 | C38: 700 | D38: =B38*C38 -> 1400 | E38: 16-channel, protocol decode
A39: Function generator (Rigol DG1062Z) | B39: 1 | C39: 480 | D39: =B39*C39 -> 480 | E39: 60 MHz, 2-channel
A40: LCR meter (component verification) | B40: 1 | C40: 850 | D40: =B40*C40 -> 850 | E40: Incoming inspection
A41: ICT / flying probe fixture (custom) | B41: 1 | C41: 5500 | D41: =B41*C41 -> 5500 | E41: Board-level in-circuit test
A42: Thermal camera (FLIR C5 or equiv.) | B42: 1 | C42: 1200 | D42: =B42*C42 -> 1200 | E42: Thermal profiling, fault detection
A43: J-Link / ST-Link programmers (bulk) | B43: 8 | C43: 85 | D43: =B43*C43 -> 680 | E43: MCU programming & debug probes
A44: Subtotal — Test & Measurement | D44: =SUM(D35:D43) -> 13770
...

Sheet Monthly Operating
A1: MONTHLY OPERATING COSTS — YEAR 1 STEADY STATE
A2: Assumes 4 employees by Month 6. Payroll detail on Payroll tab.
A4: Category | B4: Monthly | C4: Annual | D4: Notes
A5: FACILITY
A6: Rent (4,000 sq ft × $9/sq ft TMI) | B6: =Assumptions!B8 -> 3000 | C6: =B6*12 -> 36000 | D6: All-in gross lease including TMI
A7: Electricity | B7: =Assumptions!B15 -> 348.075 | C7: =B7*12 -> 4176.9 | D7: ~3,500 kWh/mo after OER rebate
A8: Natural Gas / Heating | B8: 280 | C8: =B8*12 -> 3360 | D8: Enbridge commercial — seasonal avg
A9: Water / Sewer | B9: 85 | C9: =B9*12 -> 1020 | D9: City of Hamilton commercial rate
A10: Waste / Recycling (incl. e-waste) | B10: 120 | C10: =B10*12 -> 1440 | D10: Commercial pickup + e-waste disposal
A11: Subtotal — Facility | B11: =SUM(B6:B10) -> 3833.075 | C11: =B11*12 -> 45996.9
A13: INSURANCE & PROFESSIONAL
A14: Commercial Insurance (CGL + property + E&O) | B14: =Assumptions!B32/12 -> 708.33333 | C14: =B14*12 -> 8500 | D14: Annual premium amortized monthly
A15: Accounting / Bookkeeping / Legal | B15: =Assumptions!B34/12 -> 1000 | C15: =B15*12 -> 12000
A16: Subtotal — Insurance & Professional | B16: =SUM(B14:B15) -> 1708.3333 | C16: =B16*12 -> 20500
A18: TECHNOLOGY & COMMUNICATIONS
A19: Internet / Telecom | B19: =Assumptions!B33 -> 350 | C19: =B19*12 -> 4200
A20: Software Licenses (EDA, ERP, cloud) | B20: =Assumptions!B36 -> 500 | C20: =B20*12 -> 6000
A21: Cloud / Hosting / Backups | B21: 150 | C21: =B21*12 -> 1800 | D21: AWS/Azure + offsite backup
A22: Subtotal — Technology | B22: =SUM(B19:B21) -> 1000 | C22: =B22*12 -> 12000
A24: OPERATIONS & CONSUMABLES
A25: Solder paste / flux / solder wire | B25: 350 | C25: =B25*12 -> 4200 | D25: Lead-free SAC305 paste + no-clean flux
A26: Soldering tips / nozzles / consumables | B26: 120 | C26: =B26*12 -> 1440
A27: ESD consumables (wrist straps, mats, bags) | B27: 100 | C27: =B27*12 -> 1200
A28: Shipping / Courier / Freight | B28: =Assumptions!B37 -> 600 | C28: =B28*12 -> 7200
A29: Office Supplies / Misc | B29: =Assumptions!B35 -> 400 | C29: =B29*12 -> 4800
A30: Equipment Maintenance / Calibration | B30: 250 | C30: =B30*12 -> 3000 | D30: Annual cal amortized + preventive maint
A31: Subtotal — Operations & Consumables | B31: =SUM(B25:B30) -> 1820 | C31: =B31*12 -> 21840
A33: TOTAL OVERHEAD (BEFORE PAYROLL) | B33: =B11+B16+B22+B31 -> 8361.4083 | C33: =B33*12 -> 100336.9

Sheet Payroll
A1: PAYROLL COST DETAIL — YEAR 1 TEAM
A2: Employer total cost per employee including all statutory contributions (2026 Ontario rates)
A4: Role | B4: Annual Salary | C4: CPP (ER) | D4: EI (ER) | E4: WSIB | F4: Vacation 4% | G4: Total ER Cost | H4: Monthly Cost
A5: Founder / GM (you — salary draw) | B5: 55000 | C5: =Assumptions!B19*(MIN(B5,Assumptions!B21)-Assumptions!B20) -> 3064.25 | D5: =MIN(B5*Assumptions!B23,Assumptions!B25) -> 1255.1 | E5: =B5*Assumptions!B26 -> 676.5 | F5: =B5*Assumptions!B27 -> 2200 | G5: =SUM(B5:F5) -> 62195.85 | H5: =G5/12 -> 5182.9875
A6: Electronics Assembler / Technician | B6: 48000 | C6: =Assumptions!B19*(MIN(B6,Assumptions!B21)-Assumptions!B20) -> 2647.75 | D6: =MIN(B6*Assumptions!B23,Assumptions!B25) -> 1095.36 | E6: =B6*Assumptions!B26 -> 590.4 | F6: =B6*Assumptions!B27 -> 1920 | G6: =SUM(B6:F6) -> 54253.51 | H6: =G6/12 -> 4521.1258
A7: Firmware Developer (assembly/C) | B7: 72000 | C7: =Assumptions!B19*(MIN(B7,Assumptions!B21)-Assumptions!B20) -> 4075.75 | D7: =MIN(B7*Assumptions!B23,Assumptions!B25) -> 1572.3 | E7: =B7*Assumptions!B26 -> 885.6 | F7: =B7*Assumptions!B27 -> 2880 | G7: =SUM(B7:F7) -> 81413.65 | H7: =G7/12 -> 6784.4708
A8: Production Coordinator / QC | B8: 45000 | C8: =Assumptions!B19*(MIN(B8,Assumptions!B21)-Assumptions!B20) -> 2469.25 | D8: =MIN(B8*Assumptions!B23,Assumptions!B25) -> 1026.9 | E8: =B8*Assumptions!B26 -> 553.5 | F8: =B8*Assumptions!B27 -> 1800 | G8: =SUM(B8:F8) -> 50849.65 | H8: =G8/12 -> 4237.4708
A10: TOTAL ANNUAL PAYROLL (4 employees) | B10: =SUM(B5:B8) -> 220000 | C10: =SUM(C5:C8) -> 12257 | D10: =SUM(D5:D8) -> 4949.66 | E10: =SUM(E5:E8) -> 2706 | F10: =SUM(F5:F8) -> 8800 | G10: =SUM(G5:G8) -> 248712.66 | H10: =SUM(H5:H8) -> 20726.055
A12: Employer Burden Summary
A13: Total Base Salaries | B13: =B10 -> 220000
A14: Total Employer Contributions | B14: =G10-B10 -> 28712.66
A15: Effective Burden Rate | B15: =B14/B13 -> 0.13051209 | D15: Typically 9–16% for Ontario employers
A17: Monthly Payroll (total employer cost) | B17: =G10/12 -> 20726.055

Sheet Year 1 Summary
A1: YEAR 1 COST SUMMARY
A2: Total cost of operations — startup capital + 12 months operating + payroll
A4: Category | B4: Annual | C4: Monthly Avg | D4: Notes
A5: ONE-TIME STARTUP CAPITAL
A6: Total Startup Investment | B6: ='Startup Capital'!D74 -> 278681 | C6: =B6/12 -> 23223.417 | D6: One-time — amortized for monthly reference only
A8: ANNUAL OPERATING COSTS
A9: Facility (rent, utilities, waste) | B9: ='Monthly Operating'!C11 -> 45996.9 | C9: =B9/12 -> 3833.075
A10: Insurance & Professional | B10: ='Monthly Operating'!C16 -> 20500 | C10: =B10/12 -> 1708.3333
A11: Technology & Communications | B11: ='Monthly Operating'!C22 -> 12000 | C11: =B11/12 -> 1000
A12: Operations & Consumables | B12: ='Monthly Operating'!C31 -> 21840 | C12: =B12/12 -> 1820
A13: Payroll (4 employees, all-in) | B13: =Payroll!G10 -> 248712.66 | C13: =B13/12 -> 20726.055 | D13: Includes CPP, EI, WSIB, vacation pay
A14: TOTAL ANNUAL OPERATING | B14: =SUM(B8:B13) -> 349049.56 | C14: =B14/12 -> 29087.463
A16: YEAR 1 TOTAL CASH REQUIREMENT | B16: =B6+B14 -> 627730.56
A18: MONTHLY BURN RATE (operating only) | B18: =C14 -> 29087.463 | D18: What you need to cover each month after startup
A19: MONTHS OF RUNWAY (with 3-mo reserve) | B19: =45000/C14 -> 1.5470582 | D19: Based on $45K operating reserve in startup capital
